Workbook

Sheet README
A1: TR-2024-01 생활관 면적산정 엑셀 템플릿 (권장/기본 기준)
A3: 사용 방법
A4: 1) INPUTS 시트에서 'Mode(권장/기본)'와 수용인원(일반/전체)을 입력합니다.
A5: 2) CALC 시트에서 공간별 면적, 비공용면적 합계, 공용면적(비율), 총연면적, ㎡/인 결과를 확인합니다.
A6: 3) LOOKUP 시트에서 100~1400명(100명 단위) 결과 테이블을 확인/복사해 사용합니다.
A8: 설정값(기준) 요약
A9: - 권장(Recommended): 공용공간 비율 35%, 스터디라운지 39.6㎡ × (전체사생수/20)
A10: - 기본(Basic): 공용공간 비율 29%, 스터디라운지 39.6㎡ × (전체사생수/40) (권장의 50%)
A12: 주의
A13: - 보고서 원문의 '전체 사생수' 정의가 프로젝트마다 달라질 수 있으므로, 본 템플릿은 TotalResidents를 별도 입력값으로 둡니다.
A14: - 본 템플릿의 모듈수 산정은 CEILING(… ,1)로 올림 처리(설비/프로그램 수량은 부족 방지)합니다.
A16: 출처(보고서): TR-2024-01(국립대 생활관 시설 면적 산정 가이드라인 개발), 표 V-1, V-2 및 부록2~3

Sheet INPUTS
A1: 입력(파라미터)
A3: Mode | B3: Recommended
A4: GeneralResidents (일반 사생수, 명) | B4: 800
A5: TotalResidents (전체 사생수, 명) ※기본값=일반사생수 | B5: =B4 -> 800
A7: 공용공간 비율 (권장) | B7: 0.35
A8: 공용공간 비율 (기본) | B8: 0.29

Sheet MODULES
A1: 모듈(기준면적) 상수
A2: Code | B2: Description | C2: Area(㎡)
A3: M13.2 | B3: 소규모 실(경비/당직/근로자휴게 등) | C3: 13.2
A4: M26.4 | B4: 중규모 실(사감실/공유주방 단위/보관실 단위 등) | C4: 26.4
A5: M39.6 | B5: 라운지/세탁 단위 | C5: 39.6
A6: M66.0 | B6: 체력단련실 단위 | C6: 66
A7: M92.4 | B7: 편의점(고정) | C7: 92.4
A8: M105.6 | B8: 행정 라운지(고정) | C8: 105.6

Sheet RULES_RECOMM
A1: 산정 룰 테이블 (권장)
A3: Category | B3: Space | C3: CalcType | D3: Multiplier(㎡) | E3: Divisor | F3: FixedArea(㎡) | G3: Units Formula | H3: Area Formula
A4: 주거생활공간 | B4: 일반 사생실 | C4: PER_ROOM | D4: 26.4 | E4: 2 | G4: =CEILING(INPUTS!$B$4/2,1) -> 400 | H4: =26.4*CEILING(INPUTS!$B$4/2,1) -> 10560
A5: 학습지원공간 | B5: 스터디라운지 | C5: PER_RESIDENT | D5: 39.6 | E5: 20 | G5: =CEILING(INPUTS!$B$5/20,1) -> 40 | H5: =39.6*CEILING(INPUTS!$B$5/20,1) -> 1584
A6: 생활편의공간 | B6: 체력단련실 | C6: PER_RESIDENT | D6: 66 | E6: 330 | G6: =CEILING(INPUTS!$B$5/330,1) -> 3 | H6: =66*CEILING(INPUTS!$B$5/330,1) -> 198
A7: 생활편의공간 | B7: 공유주방 | C7: PER_RESIDENT | D7: 26.4 | E7: 180 | G7: =CEILING(INPUTS!$B$5/180,1) -> 5 | H7: =26.4*CEILING(INPUTS!$B$5/180,1) -> 132
A8: 생활편의공간 | B8: 공동세탁실 | C8: PER_RESIDENT | D8: 39.6 | E8: 300 | G8: =CEILING(INPUTS!$B$5/300,1) -> 3 | H8: =39.6*CEILING(INPUTS!$B$5/300,1) -> 118.8
A9: 생활편의공간 | B9: 짐·택배 통합보관실 | C9: PER_RESIDENT | D9: 26.4 | E9: 150 | G9: =CEILING(INPUTS!$B$5/150,1) -> 6 | H9: =26.4*CEILING(INPUTS!$B$5/150,1) -> 158.4
A10: 생활편의공간 | B10: 편의점 | C10: FIXED | F10: 92.4 | G10: =1 -> 1 | H10: =92.4 -> 92.4
A11: 관리행정공간 | B11: 행정라운지 | C11: FIXED | F11: 105.6 | G11: =1 -> 1 | H11: =105.6 -> 105.6
A12: 관리행정공간 | B12: 경비실 | C12: FIXED | F12: 13.2 | G12: =1 -> 1 | H12: =13.2 -> 13.2
A13: 관리행정공간 | B13: 당직실 | C13: FIXED | F13: 13.2 | G13: =1 -> 1 | H13: =13.2 -> 13.2
A14: 관리행정공간 | B14: 근로자휴게실 | C14: FIXED | F14: 13.2 | G14: =1 -> 1 | H14: =13.2 -> 13.2
A15: 관리행정공간 | B15: 사감실(남) | C15: FIXED | F15: 26.4 | G15: =1 -> 1 | H15: =26.4 -> 26.4
A16: 관리행정공간 | B16: 사감실(여) | C16: FIXED | F16: 26.4 | G16: =1 -> 1 | H16: =26.4 -> 26.4
A17: 공용공간 | B17: 공용공간(복도/계단/설비 등) | C17: PERCENT_OF_TOTAL | H17: '=TotalGFA*INPUTS!$B$7

Sheet RULES_BASIC
A1: 산정 룰 테이블 (기본)
A3: Category | B3: Space | C3: CalcType | D3: Multiplier(㎡) | E3: Divisor | F3: FixedArea(㎡) | G3: Units Formula | H3: Area Formula
A4: 주거생활공간 | B4: 일반 사생실 | C4: PER_ROOM | D4: 26.4 | E4: 2 | G4: =CEILING(INPUTS!$B$4/2,1) -> 400 | H4: =26.4*CEILING(INPUTS!$B$4/2,1) -> 10560
A5: 학습지원공간 | B5: 스터디라운지 | C5: PER_RESIDENT | D5: 39.6 | E5: 40 | G5: =CEILING(INPUTS!$B$5/40,1) -> 20 | H5: =39.6*CEILING(INPUTS!$B$5/40,1) -> 792
A6: 생활편의공간 | B6: 체력단련실 | C6: PER_RESIDENT | D6: 66 | E6: 330 | G6: =CEILING(INPUTS!$B$5/330,1) -> 3 | H6: =66*CEILING(INPUTS!$B$5/330,1) -> 198
A7: 생활편의공간 | B7: 공유주방 | C7: PER_RESIDENT | D7: 26.4 | E7: 180 | G7: =CEILING(INPUTS!$B$5/180,1) -> 5 | H7: =26.4*CEILING(INPUTS!$B$5/180,1) -> 132
A8: 생활편의공간 | B8: 공동세탁실 | C8: PER_RESIDENT | D8: 39.6 | E8: 300 | G8: =CEILING(INPUTS!$B$5/300,1) -> 3 | H8: =39.6*CEILING(INPUTS!$B$5/300,1) -> 118.8
A9: 생활편의공간 | B9: 짐·택배 통합보관실 | C9: PER_RESIDENT | D9: 26.4 | E9: 150 | G9: =CEILING(INPUTS!$B$5/150,1) -> 6 | H9: =26.4*CEILING(INPUTS!$B$5/150,1) -> 158.4
A10: 생활편의공간 | B10: 편의점 | C10: FIXED | F10: 92.4 | G10: =1 -> 1 | H10: =92.4 -> 92.4
A11: 관리행정공간 | B11: 행정라운지 | C11: FIXED | F11: 105.6 | G11: =1 -> 1 | H11: =105.6 -> 105.6
A12: 관리행정공간 | B12: 경비실 | C12: FIXED | F12: 13.2 | G12: =1 -> 1 | H12: =13.2 -> 13.2
A13: 관리행정공간 | B13: 당직실 | C13: FIXED | F13: 13.2 | G13: =1 -> 1 | H13: =13.2 -> 13.2
A14: 관리행정공간 | B14: 근로자휴게실 | C14: FIXED | F14: 13.2 | G14: =1 -> 1 | H14: =13.2 -> 13.2
A15: 관리행정공간 | B15: 사감실(남) | C15: FIXED | F15: 26.4 | G15: =1 -> 1 | H15: =26.4 -> 26.4
A16: 관리행정공간 | B16: 사감실(여) | C16: FIXED | F16: 26.4 | G16: =1 -> 1 | H16: =26.4 -> 26.4
A17: 공용공간 | B17: 공용공간(복도/계단/설비 등) | C17: PERCENT_OF_TOTAL | H17: '=TotalGFA*INPUTS!$B$8

Sheet CALC
A1: 계산 결과 (Mode에 따라 자동 선택)
A3: Mode | B3: =INPUTS!$B$3 -> Recommended
A4: GeneralResidents | B4: =INPUTS!$B$4 -> 800
A5: TotalResidents | B5: =INPUTS!$B$5 -> 800
A8: 권장 기준(Recommended) 계산 | F8: 기본 기준(Basic) 계산
A9: Category | B9: Space | C9: Units | D9: Area(㎡) | F9: Category | G9: Space | H9: Units | I9: Area(㎡)
A10: 주거생활공간 | B10: 일반 사생실 | C10: =RULES_RECOMM!$G$4 -> 400 | D10: =RULES_RECOMM!$H$4 -> 10560 | F10: 주거생활공간 | G10: 일반 사생실 | H10: =RULES_BASIC!$G$4 -> 400 | I10: =RULES_BASIC!$H$4 -> 10560
A11: 학습지원공간 | B11: 스터디라운지 | C11: =RULES_RECOMM!$G$5 -> 40 | D11: =RULES_RECOMM!$H$5 -> 1584 | F11: 학습지원공간 | G11: 스터디라운지 | H11: =RULES_BASIC!$G$5 -> 20 | I11: =RULES_BASIC!$H$5 -> 792
A12: 생활편의공간 | B12: 체력단련실 | C12: =RULES_RECOMM!$G$6 -> 3 | D12: =RULES_RECOMM!$H$6 -> 198 | F12: 생활편의공간 | G12: 체력단련실 | H12: =RULES_BASIC!$G$6 -> 3 | I12: =RULES_BASIC!$H$6 -> 198
A13: 생활편의공간 | B13: 공유주방 | C13: =RULES_RECOMM!$G$7 -> 5 | D13: =RULES_RECOMM!$H$7 -> 132 | F13: 생활편의공간 | G13: 공유주방 | H13: =RULES_BASIC!$G$7 -> 5 | I13: =RULES_BASIC!$H$7 -> 132
A14: 생활편의공간 | B14: 공동세탁실 | C14: =RULES_RECOMM!$G$8 -> 3 | D14: =RULES_RECOMM!$H$8 -> 118.8 | F14: 생활편의공간 | G14: 공동세탁실 | H14: =RULES_BASIC!$G$8 -> 3 | I14: =RULES_BASIC!$H$8 -> 118.8
A15: 생활편의공간 | B15: 짐·택배 통합보관실 | C15: =RULES_RECOMM!$G$9 -> 6 | D15: =RULES_RECOMM!$H$9 -> 158.4 | F15: 생활편의공간 | G15: 짐·택배 통합보관실 | H15: =RULES_BASIC!$G$9 -> 6 | I15: =RULES_BASIC!$H$9 -> 158.4
A16: 생활편의공간 | B16: 편의점 | C16: =RULES_RECOMM!$G$10 -> 1 | D16: =RULES_RECOMM!$H$10 -> 92.4 | F16: 생활편의공간 | G16: 편의점 | H16: =RULES_BASIC!$G$10 -> 1 | I16: =RULES_BASIC!$H$10 -> 92.4
A17: 관리행정공간 | B17: 행정라운지 | C17: =RULES_RECOMM!$G$11 -> 1 | D17: =RULES_RECOMM!$H$11 -> 105.6 | F17: 관리행정공간 | G17: 행정라운지 | H17: =RULES_BASIC!$G$11 -> 1 | I17: =RULES_BASIC!$H$11 -> 105.6
A18: 관리행정공간 | B18: 경비실 | C18: =RULES_RECOMM!$G$12 -> 1 | D18: =RULES_RECOMM!$H$12 -> 13.2 | F18: 관리행정공간 | G18: 경비실 | H18: =RULES_BASIC!$G$12 -> 1 | I18: =RULES_BASIC!$H$12 -> 13.2
A19: 관리행정공간 | B19: 당직실 | C19: =RULES_RECOMM!$G$13 -> 1 | D19: =RULES_RECOMM!$H$13 -> 13.2 | F19: 관리행정공간 | G19: 당직실 | H19: =RULES_BASIC!$G$13 -> 1 | I19: =RULES_BASIC!$H$13 -> 13.2
A20: 관리행정공간 | B20: 근로자휴게실 | C20: =RULES_RECOMM!$G$14 -> 1 | D20: =RULES_RECOMM!$H$14 -> 13.2 | F20: 관리행정공간 | G20: 근로자휴게실 | H20: =RULES_BASIC!$G$14 -> 1 | I20: =RULES_BASIC!$H$14 -> 13.2
A21: 관리행정공간 | B21: 사감실(남) | C21: =RULES_RECOMM!$G$15 -> 1 | D21: =RULES_RECOMM!$H$15 -> 26.4 | F21: 관리행정공간 | G21: 사감실(남) | H21: =RULES_BASIC!$G$15 -> 1 | I21: =RULES_BASIC!$H$15 -> 26.4
A22: 관리행정공간 | B22: 사감실(여) | C22: =RULES_RECOMM!$G$16 -> 1 | D22: =RULES_RECOMM!$H$16 -> 26.4 | F22: 관리행정공간 | G22: 사감실(여) | H22: =RULES_BASIC!$G$16 -> 1 | I22: =RULES_BASIC!$H$16 -> 26.4
C24: 비공용면적 합계 | D24: =SUM(D10:D22) -> 13041.6 | H24: 비공용면적 합계 | I24: =SUM(I10:I22) -> 12249.6
C25: 총연면적(TotalGFA) | D25: =D24/(1-INPUTS!$B$7) -> 20064 | H25: 총연면적(TotalGFA) | I25: =I24/(1-INPUTS!$B$8) -> 17252.958
C26: 공용공간 면적(CommonArea) | D26: =D25*INPUTS!$B$7 -> 7022.4 | H26: 공용공간 면적(CommonArea) | I26: =I25*INPUTS!$B$8 -> 5003.3577
C27: ㎡/인 (총연면적/일반사생수) | D27: =IF($B$4=0,"",D25/$B$4) -> 25.08 | H27: ㎡/인 (총연면적/일반사생수) | I27: =IF($B$4=0,"",I25/$B$4) -> 21.566197
A32: 선택 결과 (Mode 기반)
A33: Category | B33: Space | C33: Area(㎡) - Selected
A34: 주거생활공간 | B34: 일반 사생실 | C34: =IF($B$3="Recommended",D10,I10) -> 10560
A35: 학습지원공간 | B35: 스터디라운지 | C35: =IF($B$3="Recommended",D11,I11) -> 1584
A36: 생활편의공간 | B36: 체력단련실 | C36: =IF($B$3="Recommended",D12,I12) -> 198
A37: 생활편의공간 | B37: 공유주방 | C37: =IF($B$3="Recommended",D13,I13) -> 132
A38: 생활편의공간 | B38: 공동세탁실 | C38: =IF($B$3="Recommended",D14,I14) -> 118.8
A39: 생활편의공간 | B39: 짐·택배 통합보관실 | C39: =IF($B$3="Recommended",D15,I15) -> 158.4
A40: 생활편의공간 | B40: 편의점 | C40: =IF($B$3="Recommended",D16,I16) -> 92.4
A41: 관리행정공간 | B41: 행정라운지 | C41: =IF($B$3="Recommended",D17,I17) -> 105.6
A42: 관리행정공간 | B42: 경비실 | C42: =IF($B$3="Recommended",D18,I18) -> 13.2
A43: 관리행정공간 | B43: 당직실 | C43: =IF($B$3="Recommended",D19,I19) -> 13.2
A44: 관리행정공간 | B44: 근로자휴게실 | C44: =IF($B$3="Recommended",D20,I20) -> 13.2
A45: 관리행정공간 | B45: 사감실(남) | C45: =IF($B$3="Recommended",D21,I21) -> 26.4
A46: 관리행정공간 | B46: 사감실(여) | C46: =IF($B$3="Recommended",D22,I22) -> 26.4
A47: 공용공간 | B47: 공용공간(복도/계단/설비 등) | C47: =IF($B$3="Recommended",D26,I26) -> 7022.4
B49: 총연면적(TotalGFA) - Selected | C49: =IF($B$3="Recommended",D25,I25) -> 20064
...

Sheet LOOKUP
A1: 100~1400명(100명 단위) 룩업 테이블 (보고서 부록2~3 대응)
A3: N(일반사생수) | B3: Mode | C3: 일반 사생실 | D3: 스터디라운지 | E3: 체력단련실 | F3: 공유주방 | G3: 공동세탁실 | H3: 짐·택배 | I3: 편의점 | J3: 행정라운지 | K3: 경비실 | L3: 당직실 | M3: 근로자휴게 | N3: 사감(남) | O3: 사감(여) | P3: 비공용면적합 | Q3: 총연면적 | R3: 공용면적 | S3: ㎡/인
A4: 100 | B4: Recommended | C4: =26.4*CEILING($A4/2,1) -> 1320 | D4: =39.6*CEILING($A4/20,1) -> 198 | E4: =66*CEILING($A4/330,1) -> 66 | F4: =26.4*CEILING($A4/180,1) -> 26.4 | G4: =39.6*CEILING($A4/300,1) -> 39.6 | H4: =26.4*CEILING($A4/150,1) -> 26.4 | I4: =92.4 -> 92.4 | J4: =105.6 -> 105.6 | K4: =13.2 -> 13.2 | L4: =13.2 -> 13.2 | M4: =13.2 -> 13.2 | N4: =26.4 -> 26.4 | O4: =26.4 -> 26.4 | P4: =SUM(C4:O4) -> 1966.8 | Q4: =P4/(1-INPUTS!$B$7) -> 3025.8462 | R4: =Q4*INPUTS!$B$7 -> 1059.0462 | S4: =Q4/$A4 -> 30.258462
A5: 200 | B5: Recommended | C5: =26.4*CEILING($A5/2,1) -> 2640 | D5: =39.6*CEILING($A5/20,1) -> 396 | E5: =66*CEILING($A5/330,1) -> 66 | F5: =26.4*CEILING($A5/180,1) -> 52.8 | G5: =39.6*CEILING($A5/300,1) -> 39.6 | H5: =26.4*CEILING($A5/150,1) -> 52.8 | I5: =92.4 -> 92.4 | J5: =105.6 -> 105.6 | K5: =13.2 -> 13.2 | L5: =13.2 -> 13.2 | M5: =13.2 -> 13.2 | N5: =26.4 -> 26.4 | O5: =26.4 -> 26.4 | P5: =SUM(C5:O5) -> 3537.6 | Q5: =P5/(1-INPUTS!$B$7) -> 5442.4615 | R5: =Q5*INPUTS!$B$7 -> 1904.8615 | S5: =Q5/$A5 -> 27.212308
A6: 300 | B6: Recommended | C6: =26.4*CEILING($A6/2,1) -> 3960 | D6: =39.6*CEILING($A6/20,1) -> 594 | E6: =66*CEILING($A6/330,1) -> 66 | F6: =26.4*CEILING($A6/180,1) -> 52.8 | G6: =39.6*CEILING($A6/300,1) -> 39.6 | H6: =26.4*CEILING($A6/150,1) -> 52.8 | I6: =92.4 -> 92.4 | J6: =105.6 -> 105.6 | K6: =13.2 -> 13.2 | L6: =13.2 -> 13.2 | M6: =13.2 -> 13.2 | N6: =26.4 -> 26.4 | O6: =26.4 -> 26.4 | P6: =SUM(C6:O6) -> 5055.6 | Q6: =P6/(1-INPUTS!$B$7) -> 7777.8462 | R6: =Q6*INPUTS!$B$7 -> 2722.2462 | S6: =Q6/$A6 -> 25.926154
A7: 400 | B7: Recommended | C7: =26.4*CEILING($A7/2,1) -> 5280 | D7: =39.6*CEILING($A7/20,1) -> 792 | E7: =66*CEILING($A7/330,1) -> 132 | F7: =26.4*CEILING($A7/180,1) -> 79.2 | G7: =39.6*CEILING($A7/300,1) -> 79.2 | H7: =26.4*CEILING($A7/150,1) -> 79.2 | I7: =92.4 -> 92.4 | J7: =105.6 -> 105.6 | K7: =13.2 -> 13.2 | L7: =13.2 -> 13.2 | M7: =13.2 -> 13.2 | N7: =26.4 -> 26.4 | O7: =26.4 -> 26.4 | P7: =SUM(C7:O7) -> 6732 | Q7: =P7/(1-INPUTS!$B$7) -> 10356.923 | R7: =Q7*INPUTS!$B$7 -> 3624.9231 | S7: =Q7/$A7 -> 25.892308
A8: 500 | B8: Recommended | C8: =26.4*CEILING($A8/2,1) -> 6600 | D8: =39.6*CEILING($A8/20,1) -> 990 | E8: =66*CEILING($A8/330,1) -> 132 | F8: =26.4*CEILING($A8/180,1) -> 79.2 | G8: =39.6*CEILING($A8/300,1) -> 79.2 | H8: =26.4*CEILING($A8/150,1) -> 105.6 | I8: =92.4 -> 92.4 | J8: =105.6 -> 105.6 | K8: =13.2 -> 13.2 | L8: =13.2 -> 13.2 | M8: =13.2 -> 13.2 | N8: =26.4 -> 26.4 | O8: =26.4 -> 26.4 | P8: =SUM(C8:O8) -> 8276.4 | Q8: =P8/(1-INPUTS!$B$7) -> 12732.923 | R8: =Q8*INPUTS!$B$7 -> 4456.5231 | S8: =Q8/$A8 -> 25.465846
A9: 600 | B9: Recommended | C9: =26.4*CEILING($A9/2,1) -> 7920 | D9: =39.6*CEILING($A9/20,1) -> 1188 | E9: =66*CEILING($A9/330,1) -> 132 | F9: =26.4*CEILING($A9/180,1) -> 105.6 | G9: =39.6*CEILING($A9/300,1) -> 79.2 | H9: =26.4*CEILING($A9/150,1) -> 105.6 | I9: =92.4 -> 92.4 | J9: =105.6 -> 105.6 | K9: =13.2 -> 13.2 | L9: =13.2 -> 13.2 | M9: =13.2 -> 13.2 | N9: =26.4 -> 26.4 | O9: =26.4 -> 26.4 | P9: =SUM(C9:O9) -> 9820.8 | Q9: =P9/(1-INPUTS!$B$7) -> 15108.923 | R9: =Q9*INPUTS!$B$7 -> 5288.1231 | S9: =Q9/$A9 -> 25.181538
A10: 700 | B10: Recommended | C10: =26.4*CEILING($A10/2,1) -> 9240 | D10: =39.6*CEILING($A10/20,1) -> 1386 | E10: =66*CEILING($A10/330,1) -> 198 | F10: =26.4*CEILING($A10/180,1) -> 105.6 | G10: =39.6*CEILING($A10/300,1) -> 118.8 | H10: =26.4*CEILING($A10/150,1) -> 132 | I10: =92.4 -> 92.4 | J10: =105.6 -> 105.6 | K10: =13.2 -> 13.2 | L10: =13.2 -> 13.2 | M10: =13.2 -> 13.2 | N10: =26.4 -> 26.4 | O10: =26.4 -> 26.4 | P10: =SUM(C10:O10) -> 11470.8 | Q10: =P10/(1-INPUTS!$B$7) -> 17647.385 | R10: =Q10*INPUTS!$B$7 -> 6176.5846 | S10: =Q10/$A10 -> 25.210549
A11: 800 | B11: Recommended | C11: =26.4*CEILING($A11/2,1) -> 10560 | D11: =39.6*CEILING($A11/20,1) -> 1584 | E11: =66*CEILING($A11/330,1) -> 198 | F11: =26.4*CEILING($A11/180,1) -> 132 | G11: =39.6*CEILING($A11/300,1) -> 118.8 | H11: =26.4*CEILING($A11/150,1) -> 158.4 | I11: =92.4 -> 92.4 | J11: =105.6 -> 105.6 | K11: =13.2 -> 13.2 | L11: =13.2 -> 13.2 | M11: =13.2 -> 13.2 | N11: =26.4 -> 26.4 | O11: =26.4 -> 26.4 | P11: =SUM(C11:O11) -> 13041.6 | Q11: =P11/(1-INPUTS!$B$7) -> 20064 | R11: =Q11*INPUTS!$B$7 -> 7022.4 | S11: =Q11/$A11 -> 25.08
A12: 900 | B12: Recommended | C12: =26.4*CEILING($A12/2,1) -> 11880 | D12: =39.6*CEILING($A12/20,1) -> 1782 | E12: =66*CEILING($A12/330,1) -> 198 | F12: =26.4*CEILING($A12/180,1) -> 132 | G12: =39.6*CEILING($A12/300,1) -> 118.8 | H12: =26.4*CEILING($A12/150,1) -> 158.4 | I12: =92.4 -> 92.4 | J12: =105.6 -> 105.6 | K12: =13.2 -> 13.2 | L12: =13.2 -> 13.2 | M12: =13.2 -> 13.2 | N12: =26.4 -> 26.4 | O12: =26.4 -> 26.4 | P12: =SUM(C12:O12) -> 14559.6 | Q12: =P12/(1-INPUTS!$B$7) -> 22399.385 | R12: =Q12*INPUTS!$B$7 -> 7839.7846 | S12: =Q12/$A12 -> 24.888205
A13: 1000 | B13: Recommended | C13: =26.4*CEILING($A13/2,1) -> 13200 | D13: =39.6*CEILING($A13/20,1) -> 1980 | E13: =66*CEILING($A13/330,1) -> 264 | F13: =26.4*CEILING($A13/180,1) -> 158.4 | G13: =39.6*CEILING($A13/300,1) -> 158.4 | H13: =26.4*CEILING($A13/150,1) -> 184.8 | I13: =92.4 -> 92.4 | J13: =105.6 -> 105.6 | K13: =13.2 -> 13.2 | L13: =13.2 -> 13.2 | M13: =13.2 -> 13.2 | N13: =26.4 -> 26.4 | O13: =26.4 -> 26.4 | P13: =SUM(C13:O13) -> 16236 | Q13: =P13/(1-INPUTS!$B$7) -> 24978.462 | R13: =Q13*INPUTS!$B$7 -> 8742.4615 | S13: =Q13/$A13 -> 24.978462
A14: 1100 | B14: Recommended | C14: =26.4*CEILING($A14/2,1) -> 14520 | D14: =39.6*CEILING($A14/20,1) -> 2178 | E14: =66*CEILING($A14/330,1) -> 264 | F14: =26.4*CEILING($A14/180,1) -> 184.8 | G14: =39.6*CEILING($A14/300,1) -> 158.4 | H14: =26.4*CEILING($A14/150,1) -> 211.2 | I14: =92.4 -> 92.4 | J14: =105.6 -> 105.6 | K14: =13.2 -> 13.2 | L14: =13.2 -> 13.2 | M14: =13.2 -> 13.2 | N14: =26.4 -> 26.4 | O14: =26.4 -> 26.4 | P14: =SUM(C14:O14) -> 17806.8 | Q14: =P14/(1-INPUTS!$B$7) -> 27395.077 | R14: =Q14*INPUTS!$B$7 -> 9588.2769 | S14: =Q14/$A14 -> 24.904615
A15: 1200 | B15: Recommended | C15: =26.4*CEILING($A15/2,1) -> 15840 | D15: =39.6*CEILING($A15/20,1) -> 2376 | E15: =66*CEILING($A15/330,1) -> 264 | F15: =26.4*CEILING($A15/180,1) -> 184.8 | G15: =39.6*CEILING($A15/300,1) -> 158.4 | H15: =26.4*CEILING($A15/150,1) -> 211.2 | I15: =92.4 -> 92.4 | J15: =105.6 -> 105.6 | K15: =13.2 -> 13.2 | L15: =13.2 -> 13.2 | M15: =13.2 -> 13.2 | N15: =26.4 -> 26.4 | O15: =26.4 -> 26.4 | P15: =SUM(C15:O15) -> 19324.8 | Q15: =P15/(1-INPUTS!$B$7) -> 29730.462 | R15: =Q15*INPUTS!$B$7 -> 10405.662 | S15: =Q15/$A15 -> 24.775385
... A17: 1400 | B17: Recommended | C17: =26.4*CEILING($A17/2,1) -> 18480 | D17: =39.6*CEILING($A17/20,1) -> 2772 | E17: =66*CEILING($A17/330,1) -> 330 | F17: =26.4*CEILING($A17/180,1) -> 211.2 | G17: =39.6*CEILING($A17/300,1) -> 198 | H17: =26.4*CEILING($A17/150,1) -> 264 | I17: =92.4 -> 92.4 | J17: =105.6 -> 105.6 | K17: =13.2 -> 13.2 | L17: =13.2 -> 13.2 | M17: =13.2 -> 13.2 | N17: =26.4 -> 26.4 | O17: =26.4 -> 26.4 | P17: =SUM(C17:O17) -> 22545.6 | Q17: =P17/(1-INPUTS!$B$7) -> 34685.538 | R17: =Q17*INPUTS!$B$7 -> 12139.938 | S17: =Q17/$A17 -> 24.775385
A20: 100 | B20: Basic | C20: =26.4*CEILING($A20/2,1) -> 1320 | D20: =39.6*CEILING($A20/40,1) -> 118.8 | E20: =66*CEILING($A20/330,1) -> 66 | F20: =26.4*CEILING($A20/180,1) -> 26.4 | G20: =39.6*CEILING($A20/300,1) -> 39.6 | H20: =26.4*CEILING($A20/150,1) -> 26.4 | I20: =92.4 -> 92.4 | J20: =105.6 -> 105.6 | K20: =13.2 -> 13.2 | L20: =13.2 -> 13.2 | M20: =13.2 -> 13.2 | N20: =26.4 -> 26.4 | O20: =26.4 -> 26.4 | P20: =SUM(C20:O20) -> 1887.6 | Q20: =P20/(1-INPUTS!$B$8) -> 2658.5915 | R20: =Q20*INPUTS!$B$8 -> 770.99155 | S20: =Q20/$A20 -> 26.585915
A21: 200 | B21: Basic | C21: =26.4*CEILING($A21/2,1) -> 2640 | D21: =39.6*CEILING($A21/40,1) -> 198 | E21: =66*CEILING($A21/330,1) -> 66 | F21: =26.4*CEILING($A21/180,1) -> 52.8 | G21: =39.6*CEILING($A21/300,1) -> 39.6 | H21: =26.4*CEILING($A21/150,1) -> 52.8 | I21: =92.4 -> 92.4 | J21: =105.6 -> 105.6 | K21: =13.2 -> 13.2 | L21: =13.2 -> 13.2 | M21: =13.2 -> 13.2 | N21: =26.4 -> 26.4 | O21: =26.4 -> 26.4 | P21: =SUM(C21:O21) -> 3339.6 | Q21: =P21/(1-INPUTS!$B$8) -> 4703.662 | R21: =Q21*INPUTS!$B$8 -> 1364.062 | S21: =Q21/$A21 -> 23.51831
A22: 300 | B22: Basic | C22: =26.4*CEILING($A22/2,1) -> 3960 | D22: =39.6*CEILING($A22/40,1) -> 316.8 | E22: =66*CEILING($A22/330,1) -> 66 | F22: =26.4*CEILING($A22/180,1) -> 52.8 | G22: =39.6*CEILING($A22/300,1) -> 39.6 | H22: =26.4*CEILING($A22/150,1) -> 52.8 | I22: =92.4 -> 92.4 | J22: =105.6 -> 105.6 | K22: =13.2 -> 13.2 | L22: =13.2 -> 13.2 | M22: =13.2 -> 13.2 | N22: =26.4 -> 26.4 | O22: =26.4 -> 26.4 | P22: =SUM(C22:O22) -> 4778.4 | Q22: =P22/(1-INPUTS!$B$8) -> 6730.1408 | R22: =Q22*INPUTS!$B$8 -> 1951.7408 | S22: =Q22/$A22 -> 22.433803
A23: 400 | B23: Basic | C23: =26.4*CEILING($A23/2,1) -> 5280 | D23: =39.6*CEILING($A23/40,1) -> 396 | E23: =66*CEILING($A23/330,1) -> 132 | F23: =26.4*CEILING($A23/180,1) -> 79.2 | G23: =39.6*CEILING($A23/300,1) -> 79.2 | H23: =26.4*CEILING($A23/150,1) -> 79.2 | I23: =92.4 -> 92.4 | J23: =105.6 -> 105.6 | K23: =13.2 -> 13.2 | L23: =13.2 -> 13.2 | M23: =13.2 -> 13.2 | N23: =26.4 -> 26.4 | O23: =26.4 -> 26.4 | P23: =SUM(C23:O23) -> 6336 | Q23: =P23/(1-INPUTS!$B$8) -> 8923.9437 | R23: =Q23*INPUTS!$B$8 -> 2587.9437 | S23: =Q23/$A23 -> 22.309859
A24: 500 | B24: Basic | C24: =26.4*CEILING($A24/2,1) -> 6600 | D24: =39.6*CEILING($A24/40,1) -> 514.8 | E24: =66*CEILING($A24/330,1) -> 132 | F24: =26.4*CEILING($A24/180,1) -> 79.2 | G24: =39.6*CEILING($A24/300,1) -> 79.2 | H24: =26.4*CEILING($A24/150,1) -> 105.6 | I24: =92.4 -> 92.4 | J24: =105.6 -> 105.6 | K24: =13.2 -> 13.2 | L24: =13.2 -> 13.2 | M24: =13.2 -> 13.2 | N24: =26.4 -> 26.4 | O24: =26.4 -> 26.4 | P24: =SUM(C24:O24) -> 7801.2 | Q24: =P24/(1-INPUTS!$B$8) -> 10987.606 | R24: =Q24*INPUTS!$B$8 -> 3186.4056 | S24: =Q24/$A24 -> 21.975211
A25: 600 | B25: Basic | C25: =26.4*CEILING($A25/2,1) -> 7920 | D25: =39.6*CEILING($A25/40,1) -> 594 | E25: =66*CEILING($A25/330,1) -> 132 | F25: =26.4*CEILING($A25/180,1) -> 105.6 | G25: =39.6*CEILING($A25/300,1) -> 79.2 | H25: =26.4*CEILING($A25/150,1) -> 105.6 | I25: =92.4 -> 92.4 | J25: =105.6 -> 105.6 | K25: =13.2 -> 13.2 | L25: =13.2 -> 13.2 | M25: =13.2 -> 13.2 | N25: =26.4 -> 26.4 | O25: =26.4 -> 26.4 | P25: =SUM(C25:O25) -> 9226.8 | Q25: =P25/(1-INPUTS!$B$8) -> 12995.493 | R25: =Q25*INPUTS!$B$8 -> 3768.693 | S25: =Q25/$A25 -> 21.659155
A26: 700 | B26: Basic | C26: =26.4*CEILING($A26/2,1) -> 9240 | D26: =39.6*CEILING($A26/40,1) -> 712.8 | E26: =66*CEILING($A26/330,1) -> 198 | F26: =26.4*CEILING($A26/180,1) -> 105.6 | G26: =39.6*CEILING($A26/300,1) -> 118.8 | H26: =26.4*CEILING($A26/150,1) -> 132 | I26: =92.4 -> 92.4 | J26: =105.6 -> 105.6 | K26: =13.2 -> 13.2 | L26: =13.2 -> 13.2 | M26: =13.2 -> 13.2 | N26: =26.4 -> 26.4 | O26: =26.4 -> 26.4 | P26: =SUM(C26:O26) -> 10797.6 | Q26: =P26/(1-INPUTS!$B$8) -> 15207.887 | R26: =Q26*INPUTS!$B$8 -> 4410.2873 | S26: =Q26/$A26 -> 21.725553
A27: 800 | B27: Basic | C27: =26.4*CEILING($A27/2,1) -> 10560 | D27: =39.6*CEILING($A27/40,1) -> 792 | E27: =66*CEILING($A27/330,1) -> 198 | F27: =26.4*CEILING($A27/180,1) -> 132 | G27: =39.6*CEILING($A27/300,1) -> 118.8 | H27: =26.4*CEILING($A27/150,1) -> 158.4 | I27: =92.4 -> 92.4 | J27: =105.6 -> 105.6 | K27: =13.2 -> 13.2 | L27: =13.2 -> 13.2 | M27: =13.2 -> 13.2 | N27: =26.4 -> 26.4 | O27: =26.4 -> 26.4 | P27: =SUM(C27:O27) -> 12249.6 | Q27: =P27/(1-INPUTS!$B$8) -> 17252.958 | R27: =Q27*INPUTS!$B$8 -> 5003.3577 | S27: =Q27/$A27 -> 21.566197
A28: 900 | B28: Basic | C28: =26.4*CEILING($A28/2,1) -> 11880 | D28: =39.6*CEILING($A28/40,1) -> 910.8 | E28: =66*CEILING($A28/330,1) -> 198 | F28: =26.4*CEILING($A28/180,1) -> 132 | G28: =39.6*CEILING($A28/300,1) -> 118.8 | H28: =26.4*CEILING($A28/150,1) -> 158.4 | I28: =92.4 -> 92.4 | J28: =105.6 -> 105.6 | K28: =13.2 -> 13.2 | L28: =13.2 -> 13.2 | M28: =13.2 -> 13.2 | N28: =26.4 -> 26.4 | O28: =26.4 -> 26.4 | P28: =SUM(C28:O28) -> 13688.4 | Q28: =P28/(1-INPUTS!$B$8) -> 19279.437 | R28: =Q28*INPUTS!$B$8 -> 5591.0366 | S28: =Q28/$A28 -> 21.421596
A29: 1000 | B29: Basic | C29: =26.4*CEILING($A29/2,1) -> 13200 | D29: =39.6*CEILING($A29/40,1) -> 990 | E29: =66*CEILING($A29/330,1) -> 264 | F29: =26.4*CEILING($A29/180,1) -> 158.4 | G29: =39.6*CEILING($A29/300,1) -> 158.4 | H29: =26.4*CEILING($A29/150,1) -> 184.8 | I29: =92.4 -> 92.4 | J29: =105.6 -> 105.6 | K29: =13.2 -> 13.2 | L29: =13.2 -> 13.2 | M29: =13.2 -> 13.2 | N29: =26.4 -> 26.4 | O29: =26.4 -> 26.4 | P29: =SUM(C29:O29) -> 15246 | Q29: =P29/(1-INPUTS!$B$8) -> 21473.239 | R29: =Q29*INPUTS!$B$8 -> 6227.2394 | S29: =Q29/$A29 -> 21.473239
A30: 1100 | B30: Basic | C30: =26.4*CEILING($A30/2,1) -> 14520 | D30: =39.6*CEILING($A30/40,1) -> 1108.8 | E30: =66*CEILING($A30/330,1) -> 264 | F30: =26.4*CEILING($A30/180,1) -> 184.8 | G30: =39.6*CEILING($A30/300,1) -> 158.4 | H30: =26.4*CEILING($A30/150,1) -> 211.2 | I30: =92.4 -> 92.4 | J30: =105.6 -> 105.6 | K30: =13.2 -> 13.2 | L30: =13.2 -> 13.2 | M30: =13.2 -> 13.2 | N30: =26.4 -> 26.4 | O30: =26.4 -> 26.4 | P30: =SUM(C30:O30) -> 16737.6 | Q30: =P30/(1-INPUTS!$B$8) -> 23574.085 | R30: =Q30*INPUTS!$B$8 -> 6836.4845 | S30: =Q30/$A30 -> 21.430986
A31: 1200 | B31: Basic | C31: =26.4*CEILING($A31/2,1) -> 15840 | D31: =39.6*CEILING($A31/40,1) -> 1188 | E31: =66*CEILING($A31/330,1) -> 264 | F31: =26.4*CEILING($A31/180,1) -> 184.8 | G31: =39.6*CEILING($A31/300,1) -> 158.4 | H31: =26.4*CEILING($A31/150,1) -> 211.2 | I31: =92.4 -> 92.4 | J31: =105.6 -> 105.6 | K31: =13.2 -> 13.2 | L31: =13.2 -> 13.2 | M31: =13.2 -> 13.2 | N31: =26.4 -> 26.4 | O31: =26.4 -> 26.4 | P31: =SUM(C31:O31) -> 18136.8 | Q31: =P31/(1-INPUTS!$B$8) -> 25544.789 | R31: =Q31*INPUTS!$B$8 -> 7407.9887 | S31: =Q31/$A31 -> 21.287324
... A33: 1400 | B33: Basic | C33: =26.4*CEILING($A33/2,1) -> 18480 | D33: =39.6*CEILING($A33/40,1) -> 1386 | E33: =66*CEILING($A33/330,1) -> 330 | F33: =26.4*CEILING($A33/180,1) -> 211.2 | G33: =39.6*CEILING($A33/300,1) -> 198 | H33: =26.4*CEILING($A33/150,1) -> 264 | I33: =92.4 -> 92.4 | J33: =105.6 -> 105.6 | K33: =13.2 -> 13.2 | L33: =13.2 -> 13.2 | M33: =13.2 -> 13.2 | N33: =26.4 -> 26.4 | O33: =26.4 -> 26.4 | P33: =SUM(C33:O33) -> 21159.6 | Q33: =P33/(1-INPUTS!$B$8) -> 29802.254 | R33: =Q33*INPUTS!$B$8 -> 8642.6535 | S33: =Q33/$A33 -> 21.287324
